<?xml version="1.0" ?>
<!-- =================================================================================== -->
<!-- |    This document was autogenerated by xacro from urdf/3w_rcup_urdf_new.xacro    | -->
<!-- |    EDITING THIS FILE BY HAND IS NOT RECOMMENDED                                 | -->
<!-- =================================================================================== -->
<robot xmlns:xacro="http://www.ros.org/wiki/xacro" name="3w_rcup_urdf_new">
  <material name="silver_default">
    <color rgba="0.700 0.700 0.700 1.000"/>
  </material>
  <material name="steel_satin">
    <color rgba="0.6274509803921569 0.6274509803921569 0.6274509803921569 1.0"/>
  </material>
  <material name="opaque272727">
    <color rgba="0.10588235294117647 0.10588235294117647 0.10588235294117647 1.0"/>
  </material>
  <transmission name="Revolute 5_tran">
    <type>transmission_interface/SimpleTransmission</type>
    <joint name="Revolute 5">
      <hardwareInterface>hardware_interface/EffortJointInterface</hardwareInterface>
    </joint>
    <actuator name="Revolute 5_actr">
      <hardwareInterface>hardware_interface/EffortJointInterface</hardwareInterface>
      <mechanicalReduction>1</mechanicalReduction>
    </actuator>
  </transmission>
  <transmission name="Revolute 6_tran">
    <type>transmission_interface/SimpleTransmission</type>
    <joint name="Revolute 6">
      <hardwareInterface>hardware_interface/EffortJointInterface</hardwareInterface>
    </joint>
    <actuator name="Revolute 6_actr">
      <hardwareInterface>hardware_interface/EffortJointInterface</hardwareInterface>
      <mechanicalReduction>1</mechanicalReduction>
    </actuator>
  </transmission>
  <transmission name="Revolute 7_tran">
    <type>transmission_interface/SimpleTransmission</type>
    <joint name="Revolute 7">
      <hardwareInterface>hardware_interface/EffortJointInterface</hardwareInterface>
    </joint>
    <actuator name="Revolute 7_actr">
      <hardwareInterface>hardware_interface/EffortJointInterface</hardwareInterface>
      <mechanicalReduction>1</mechanicalReduction>
    </actuator>
  </transmission>
  <transmission name="Revolute 15_tran">
    <type>transmission_interface/SimpleTransmission</type>
    <joint name="Revolute 15">
      <hardwareInterface>hardware_interface/EffortJointInterface</hardwareInterface>
    </joint>
    <actuator name="Revolute 15_actr">
      <hardwareInterface>hardware_interface/EffortJointInterface</hardwareInterface>
      <mechanicalReduction>1</mechanicalReduction>
    </actuator>
  </transmission>
  <transmission name="Revolute 16_tran">
    <type>transmission_interface/SimpleTransmission</type>
    <joint name="Revolute 16">
      <hardwareInterface>hardware_interface/EffortJointInterface</hardwareInterface>
    </joint>
    <actuator name="Revolute 16_actr">
      <hardwareInterface>hardware_interface/EffortJointInterface</hardwareInterface>
      <mechanicalReduction>1</mechanicalReduction>
    </actuator>
  </transmission>
  <transmission name="Revolute 17_tran">
    <type>transmission_interface/SimpleTransmission</type>
    <joint name="Revolute 17">
      <hardwareInterface>hardware_interface/EffortJointInterface</hardwareInterface>
    </joint>
    <actuator name="Revolute 17_actr">
      <hardwareInterface>hardware_interface/EffortJointInterface</hardwareInterface>
      <mechanicalReduction>1</mechanicalReduction>
    </actuator>
  </transmission>
  <link name="base_link">
    <inertial>
      <origin xyz="-0.0016765596355349697 0.010961034454487276 0.1359913404245512" rpy="0 0 0"/>
      <mass value="45.47836630248475"/>
      <inertia ixx="2.177628" iyy="2.397161" izz="1.792556" ixy="-0.008721" iyz="0.078213" ixz="-0.006159"/>
    </inertial>
    <visual>
      <origin xyz="0 0 0" rpy="0 0 0"/>
      <geometry>
        <mesh filename="package://3w_rcup_urdf_new_description/meshes/base_link.stl" scale="0.001 0.001 0.001"/>
      </geometry>
      <material name="silver_default"/>
    </visual>
    <collision>
      <origin xyz="0 0 0" rpy="0 0 0"/>
      <geometry>
        <mesh filename="package://3w_rcup_urdf_new_description/meshes/base_link.stl" scale="0.001 0.001 0.001"/>
      </geometry>
    </collision>
  </link>
  <link name="left_roller_1">
    <inertial>
      <origin xyz="-0.010694649902391953 0.00803962610329817 0.006781847703606597" rpy="0 0 0"/>
      <mass value="0.4122786652131398"/>
      <inertia ixx="0.000106" iyy="9.9e-05" izz="9.6e-05" ixy="-1e-05" iyz="8e-06" ixz="-9e-06"/>
    </inertial>
    <visual>
      <origin xyz="-0.095008 0.214003 -0.17631" rpy="0 0 0"/>
      <geometry>
        <mesh filename="package://3w_rcup_urdf_new_description/meshes/left_roller_1.stl" scale="0.001 0.001 0.001"/>
      </geometry>
      <material name="steel_satin"/>
    </visual>
    <collision>
      <origin xyz="-0.095008 0.214003 -0.17631" rpy="0 0 0"/>
      <geometry>
        <mesh filename="package://3w_rcup_urdf_new_description/meshes/left_roller_1.stl" scale="0.001 0.001 0.001"/>
      </geometry>
    </collision>
  </link>
  <link name="right_roller_1">
    <inertial>
      <origin xyz="0.01070386879259716 0.008003421622574586 0.006810021314246767" rpy="0 0 0"/>
      <mass value="0.41227866521313966"/>
      <inertia ixx="0.000106" iyy="9.9e-05" izz="9.6e-05" ixy="1.1e-05" iyz="8e-06" ixz="9e-06"/>
    </inertial>
    <visual>
      <origin xyz="0.095008 0.214003 -0.17631" rpy="0 0 0"/>
      <geometry>
        <mesh filename="package://3w_rcup_urdf_new_description/meshes/right_roller_1.stl" scale="0.001 0.001 0.001"/>
      </geometry>
      <material name="steel_satin"/>
    </visual>
    <collision>
      <origin xyz="0.095008 0.214003 -0.17631" rpy="0 0 0"/>
      <geometry>
        <mesh filename="package://3w_rcup_urdf_new_description/meshes/right_roller_1.stl" scale="0.001 0.001 0.001"/>
      </geometry>
    </collision>
  </link>
  <link name="kicker_1">
    <inertial>
      <origin xyz="-0.025188832166870394 -0.013717609182182872 -0.08108173194304436" rpy="0 0 0"/>
      <mass value="0.8809905481847389"/>
      <inertia ixx="0.009181" iyy="0.008966" izz="0.000535" ixy="5e-06" iyz="0.000274" ixz="1.1e-05"/>
    </inertial>
    <visual>
      <origin xyz="-0.025 0.100117 -0.245868" rpy="0 0 0"/>
      <geometry>
        <mesh filename="package://3w_rcup_urdf_new_description/meshes/kicker_1.stl" scale="0.001 0.001 0.001"/>
      </geometry>
      <material name="opaque272727"/>
    </visual>
    <collision>
      <origin xyz="-0.025 0.100117 -0.245868" rpy="0 0 0"/>
      <geometry>
        <mesh filename="package://3w_rcup_urdf_new_description/meshes/kicker_1.stl" scale="0.001 0.001 0.001"/>
      </geometry>
    </collision>
  </link>
  <link name="kinect_1">
    <inertial>
      <origin xyz="8.07978825644895e-05 0.03307821422428597 -0.01854148491227281" rpy="0 0 0"/>
      <mass value="5.665239174580644"/>
      <inertia ixx="0.002961" iyy="0.029846" izz="0.031012" ixy="1.5e-05" iyz="-0.0" ixz="0.0"/>
    </inertial>
    <visual>
      <origin xyz="0.0 0.11115 -0.467009" rpy="0 0 0"/>
      <geometry>
        <mesh filename="package://3w_rcup_urdf_new_description/meshes/kinect_1.stl" scale="0.001 0.001 0.001"/>
      </geometry>
      <material name="opaque272727"/>
    </visual>
    <collision>
      <origin xyz="0.0 0.11115 -0.467009" rpy="0 0 0"/>
      <geometry>
        <mesh filename="package://3w_rcup_urdf_new_description/meshes/kinect_1.stl" scale="0.001 0.001 0.001"/>
      </geometry>
    </collision>
  </link>
  <link name="front_left_wheel_1">
    <inertial>
      <origin xyz="0.01199999999999915 -9.929252031387614e-06 -9.515285583815147e-06" rpy="0 0 0"/>
      <mass value="1.3762351375635922"/>
      <inertia ixx="0.001935" iyy="0.001008" izz="0.001019" ixy="0.0" iyz="1e-06" ixz="-0.0"/>
    </inertial>
    <visual>
      <origin xyz="-0.17 0.078381 -0.015" rpy="0 0 0"/>
      <geometry>
        <mesh filename="package://3w_rcup_urdf_new_description/meshes/front_left_wheel_1.stl" scale="0.001 0.001 0.001"/>
      </geometry>
      <material name="steel_satin"/>
    </visual>
    <collision>
      <origin xyz="-0.17 0.078381 -0.015" rpy="0 0 0"/>
      <geometry>
        <mesh filename="package://3w_rcup_urdf_new_description/meshes/front_left_wheel_1.stl" scale="0.001 0.001 0.001"/>
      </geometry>
    </collision>
  </link>
  <link name="front_right_wheel_1">
    <inertial>
      <origin xyz="-0.010000000000000259 1.0026776155927508e-05 0.0020030933208660846" rpy="0 0 0"/>
      <mass value="1.3762351375635922"/>
      <inertia ixx="0.001936" iyy="0.001009" izz="0.001019" ixy="-0.0" iyz="0.0" ixz="-0.0"/>
    </inertial>
    <visual>
      <origin xyz="0.17 0.078381 -0.015" rpy="0 0 0"/>
      <geometry>
        <mesh filename="package://3w_rcup_urdf_new_description/meshes/front_right_wheel_1.stl" scale="0.001 0.001 0.001"/>
      </geometry>
      <material name="steel_satin"/>
    </visual>
    <collision>
      <origin xyz="0.17 0.078381 -0.015" rpy="0 0 0"/>
      <geometry>
        <mesh filename="package://3w_rcup_urdf_new_description/meshes/front_right_wheel_1.stl" scale="0.001 0.001 0.001"/>
      </geometry>
    </collision>
  </link>
  <link name="Component423_1">
    <inertial>
      <origin xyz="7.105427357601002e-17 3.3306690738754696e-16 0.015" rpy="0 0 0"/>
      <mass value="4.895373976646171"/>
      <inertia ixx="0.0055" iyy="0.0055" izz="0.0055" ixy="0.0" iyz="0.0" ixz="0.0"/>
    </inertial>
    <visual>
      <origin xyz="-0.0 -0.175 -0.0" rpy="0 0 0"/>
      <geometry>
        <mesh filename="package://3w_rcup_urdf_new_description/meshes/Component423_1.stl" scale="0.001 0.001 0.001"/>
      </geometry>
      <material name="steel_satin"/>
    </visual>
    <collision>
      <origin xyz="-0.0 -0.175 -0.0" rpy="0 0 0"/>
      <geometry>
        <mesh filename="package://3w_rcup_urdf_new_description/meshes/Component423_1.stl" scale="0.001 0.001 0.001"/>
      </geometry>
    </collision>
  </link>
  <joint name="Revolute 5" type="continuous">
    <origin xyz="0.095008 -0.214003 0.17631" rpy="0 0 0"/>
    <parent link="base_link"/>
    <child link="left_roller_1"/>
    <axis xyz="0.713077 -0.534564 -0.453611"/>
  </joint>
  <joint name="Revolute 6" type="continuous">
    <origin xyz="-0.095008 -0.214003 0.17631" rpy="0 0 0"/>
    <parent link="base_link"/>
    <child link="right_roller_1"/>
    <axis xyz="-0.713077 -0.534564 -0.453611"/>
  </joint>
  <joint name="Revolute 7" type="continuous">
    <origin xyz="0.025 -0.100117 0.245868" rpy="0 0 0"/>
    <parent link="base_link"/>
    <child link="kicker_1"/>
    <axis xyz="1.0 -0.0 0.0"/>
  </joint>
  <joint name="Rigid 11" type="fixed">
    <origin xyz="0.0 -0.11115 0.467009" rpy="0 0 0"/>
    <parent link="base_link"/>
    <child link="kinect_1"/>
  </joint>
  <joint name="Revolute 15" type="continuous">
    <origin xyz="0.17 -0.078381 0.015" rpy="0 0 0"/>
    <parent link="base_link"/>
    <child link="front_left_wheel_1"/>
    <axis xyz="1.0 -0.0 0.0"/>
  </joint>
  <joint name="Revolute 16" type="continuous">
    <origin xyz="-0.17 -0.078381 0.015" rpy="0 0 0"/>
    <parent link="base_link"/>
    <child link="front_right_wheel_1"/>
    <axis xyz="-1.0 0.0 -0.0"/>
  </joint>
  <joint name="Rigid 17" type="fixed">
    <origin xyz="0.0 0.175 0.0" rpy="0 0 0"/>
    <parent link="base_link"/>
    <child link="Component423_1"/>
    <!-- <axis xyz="0.856426 -0.51627 0.0"/> -->
  </joint>
</robot>
