<?xml version="1.0" ?>
<!-- =================================================================================== -->
<!-- |    This document was autogenerated by xacro from urdf/car.xacro                 | -->
<!-- |    EDITING THIS FILE BY HAND IS NOT RECOMMENDED                                 | -->
<!-- =================================================================================== -->
<robot xmlns:xacro="http://www.ros.org/wiki/xacro" name="car">
  <material name="silver_default">
    <color rgba="0.700 0.700 0.700 1.000"/>
  </material>
  <material name="abs_white">
    <color rgba="0.9647058823529412 0.9647058823529412 0.9529411764705882 1.0"/>
  </material>
  <material name="rubber_soft">
    <color rgba="0.15294117647058825 0.15294117647058825 0.15294117647058825 1.0"/>
  </material>
  <material name="paint_enamel_glossy_blue">
    <color rgba="0.18823529411764706 0.23137254901960785 0.5882352941176471 0.0"/>
  </material>
  <transmission name="Revolute 1_tran">
    <type>transmission_interface/SimpleTransmission</type>
    <joint name="Revolute 1">
      <hardwareInterface>hardware_interface/EffortJointInterface</hardwareInterface>
    </joint>
    <actuator name="Revolute 1_actr">
      <hardwareInterface>hardware_interface/EffortJointInterface</hardwareInterface>
      <mechanicalReduction>1</mechanicalReduction>
    </actuator>
  </transmission>
  <transmission name="Revolute 2_tran">
    <type>transmission_interface/SimpleTransmission</type>
    <joint name="Revolute 2">
      <hardwareInterface>hardware_interface/EffortJointInterface</hardwareInterface>
    </joint>
    <actuator name="Revolute 2_actr">
      <hardwareInterface>hardware_interface/EffortJointInterface</hardwareInterface>
      <mechanicalReduction>1</mechanicalReduction>
    </actuator>
  </transmission>
  <link name="base_link">
</link>
  <link name="chassis">
    <inertial>
      <origin xyz="7.486577157716648e-15 0.0040598158780756335 0.05309443906041509" rpy="0 0 0"/>
      <mass value="2.3230537959869224"/>
      <inertia ixx="0.00843" iyy="0.00793" izz="0.014813" ixy="0.0" iyz="-0.000356" ixz="0.0"/>
    </inertial>
    <visual>
      <origin xyz="0 0 0" rpy="0 0 0"/>
      <geometry>
        <mesh filename="file:///home/gigabtez/My project/Assets/car_description/meshes/base_link.stl" scale="0.001 0.001 0.001"/>
      </geometry>
      <material name="abs_white"/>
    </visual>
    <collision>
      <origin xyz="0 0 0" rpy="0 0 0"/>
      <geometry>
        <mesh filename="file:///home/gigabtez/My project/Assets/car_description/meshes/base_link.stl" scale="0.001 0.001 0.001"/>
      </geometry>
    </collision>
  </link>
  <link name="left_wheel_1">
    <inertial>
      <origin xyz="-0.014999999999999972 0.0 6.938893903907228e-18" rpy="0 0 0"/>
      <mass value="0.2191260875878881"/>
      <inertia ixx="0.000274" iyy="0.000153" izz="0.000153" ixy="-0.0" iyz="0.0" ixz="0.0"/>
    </inertial>
    <visual>
      <origin xyz="0.1 -0.0 -0.05" rpy="0 0 0"/>
      <geometry>
        <mesh filename="file:///home/gigabtez/My project/Assets/car_description/meshes/left_wheel_1.stl" scale="0.001 0.001 0.001"/>
      </geometry>
      <material name="rubber_soft"/>
    </visual>
    <collision>
      <origin xyz="0.1 -0.0 -0.05" rpy="0 0 0"/>
      <geometry>
        <mesh filename="file:///home/gigabtez/My project/Assets/car_description/meshes/left_wheel_1.stl" scale="0.001 0.001 0.001"/>
      </geometry>
    </collision>
  </link>
  <link name="right_wheel_1">
    <inertial>
      <origin xyz="0.014999999999999972 0.0 6.938893903907228e-18" rpy="0 0 0"/>
      <mass value="0.2191260875878881"/>
      <inertia ixx="0.000274" iyy="0.000153" izz="0.000153" ixy="0.0" iyz="0.0" ixz="-0.0"/>
    </inertial>
    <visual>
      <origin xyz="-0.1 -0.0 -0.05" rpy="0 0 0"/>
      <geometry>
        <mesh filename="file:///home/gigabtez/My project/Assets/car_description/meshes/right_wheel_1.stl" scale="0.001 0.001 0.001"/>
      </geometry>
      <material name="rubber_soft"/>
    </visual>
    <collision>
      <origin xyz="-0.1 -0.0 -0.05" rpy="0 0 0"/>
      <geometry>
        <mesh filename="file:///home/gigabtez/My project/Assets/car_description/meshes/right_wheel_1.stl" scale="0.001 0.001 0.001"/>
      </geometry>
    </collision>
  </link>
  <link name="LIDAR_1">
    <inertial>
      <origin xyz="0.0 0.0 0.012499999999999997" rpy="0 0 0"/>
      <mass value="0.11707341373143205"/>
      <inertia ixx="4.7e-05" iyy="4.7e-05" izz="8.2e-05" ixy="-0.0" iyz="-0.0" ixz="0.0"/>
    </inertial>
    <visual>
      <origin xyz="-0.0 -0.05 -0.11" rpy="0 0 0"/>
      <geometry>
        <mesh filename="file:///home/gigabtez/My project/Assets/car_description/meshes/LIDAR_1.stl" scale="0.001 0.001 0.001"/>
      </geometry>
      <material name="paint_enamel_glossy_blue"/>
    </visual>
    <collision>
      <origin xyz="-0.0 -0.05 -0.11" rpy="0 0 0"/>
      <geometry>
        <mesh filename="file:///home/gigabtez/My project/Assets/car_description/meshes/LIDAR_1.stl" scale="0.001 0.001 0.001"/>
      </geometry>
    </collision>
  </link>
  <joint name="Revolute 1" type="continuous">
    <origin xyz="-0.1 0.0 0.05" rpy="-0.707 0 0"/>
    <parent link="base_link"/>
    <child link="left_wheel_1"/>
    <axis xyz="0.0 0.0 1"/>
  </joint>
  <joint name="chassis_joint" type="fixed">
    <origin xyz="0.0 0.0 0.0" rpy="0 0 0"/>
    <parent link="base_link"/>
    <child link="chassis"/>
    <axis xyz="-1.0 0.0 0.0"/>
  </joint>
  <joint name="Revolute 2" type="continuous">
    <origin xyz="0.1 0.0 0.05" rpy="0.707 0 0"/>
    <parent link="base_link"/>
    <child link="right_wheel_1"/>
    <axis xyz="0 0.0 -1"/>
  </joint>
  <joint name="Rigid 3" type="fixed">
    <origin xyz="0.0 0.05 0.11" rpy="0 0 0"/>
    <parent link="base_link"/>
    <child link="LIDAR_1"/>
  </joint>
</robot>
