<?xml version="1.0" ?>
<robot name="rcup_urdf" xmlns:xacro="http://www.ros.org/wiki/xacro">

<xacro:include filename="$(find rcup_urdf_description)/urdf/materials.xacro" />
<xacro:include filename="$(find rcup_urdf_description)/urdf/rcup_urdf.trans" />
<xacro:include filename="$(find rcup_urdf_description)/urdf/lidar.xacro" />
<!-- <xacro:include filename="$(find rcup_urdf_description)/urdf/camera.xacro" /> -->

<link name="base_link">
  <inertial>
    <origin xyz="-0.00165859839526905 0.016307246207622854 0.13530549609314282" rpy="0 0 0"/>
    <mass value="45.95869442945325"/>
    <inertia ixx="2.222974" iyy="2.399946" izz="1.838478" ixy="-0.009129" iyz="0.104619" ixz="-0.006104"/>
  </inertial>
  <visual>
    <origin xyz="0 0 0" rpy="0 0 0"/>
    <geometry>
      <mesh filename="package://rcup_urdf_description/meshes/base_link.stl" scale="0.001 0.001 0.001"/>
    </geometry>
    <material name="silver_default"/>
  </visual>
  <collision>
    <origin xyz="0 0 0" rpy="0 0 0"/>
    <geometry>
      <mesh filename="package://rcup_urdf_description/meshes/base_link.stl" scale="0.001 0.001 0.001"/>
    </geometry>
  </collision>
</link>

<link name="Component417_1">
  <inertial>
    <origin xyz="0.010000000000001091 -6.994287818390399e-06 -3.651771739056689e-06" rpy="0 0 0"/>
    <mass value="1.3762351375635924"/>
    <inertia ixx="0.001934" iyy="0.001007" izz="0.001019" ixy="-0.0" iyz="-0.0" ixz="0.0"/>
  </inertial>
  <visual>
    <origin xyz="-0.17 -0.167619 -0.015" rpy="0 0 0"/>
    <geometry>
      <mesh filename="package://rcup_urdf_description/meshes/Component417_1.stl" scale="0.001 0.001 0.001"/>
    </geometry>
    <material name="steel_satin"/>
  </visual>
  <collision>
    <origin xyz="-0.17 -0.167619 -0.015" rpy="0 0 0"/>
    <geometry>
      <mesh filename="package://rcup_urdf_description/meshes/Component417_1.stl" scale="0.001 0.001 0.001"/>
    </geometry>
  </collision>
</link>

<link name="wheel_v1_1">
  <inertial>
    <origin xyz="-0.010000000000000175 2.6902407044088195e-05 -7.101924573045537e-07" rpy="0 0 0"/>
    <mass value="1.3762351375635924"/>
    <inertia ixx="0.001934" iyy="0.001007" izz="0.001019" ixy="0.0" iyz="1e-06" ixz="-0.0"/>
  </inertial>
  <visual>
    <origin xyz="0.17 -0.167619 -0.015" rpy="0 0 0"/>
    <geometry>
      <mesh filename="package://rcup_urdf_description/meshes/wheel_v1_1.stl" scale="0.001 0.001 0.001"/>
    </geometry>
    <material name="steel_satin"/>
  </visual>
  <collision>
    <origin xyz="0.17 -0.167619 -0.015" rpy="0 0 0"/>
    <geometry>
      <mesh filename="package://rcup_urdf_description/meshes/wheel_v1_1.stl" scale="0.001 0.001 0.001"/>
    </geometry>
  </collision>
</link>

<link name="Component419_1">
  <inertial>
    <origin xyz="-0.010694649902391953 0.00803962610329817 0.006781847703606597" rpy="0 0 0"/>
    <mass value="0.4122786652131398"/>
    <inertia ixx="0.000106" iyy="9.9e-05" izz="9.6e-05" ixy="-1e-05" iyz="8e-06" ixz="-9e-06"/>
  </inertial>
  <visual>
    <origin xyz="-0.095008 0.214003 -0.17631" rpy="0 0 0"/>
    <geometry>
      <mesh filename="package://rcup_urdf_description/meshes/Component419_1.stl" scale="0.001 0.001 0.001"/>
    </geometry>
    <material name="steel_satin"/>
  </visual>
  <collision>
    <origin xyz="-0.095008 0.214003 -0.17631" rpy="0 0 0"/>
    <geometry>
      <mesh filename="package://rcup_urdf_description/meshes/Component419_1.stl" scale="0.001 0.001 0.001"/>
    </geometry>
  </collision>
</link>

<link name="small_roller_v1_1">
  <inertial>
    <origin xyz="0.01070386879259716 0.008003421622574586 0.006810021314246767" rpy="0 0 0"/>
    <mass value="0.41227866521313966"/>
    <inertia ixx="0.000106" iyy="9.9e-05" izz="9.6e-05" ixy="1.1e-05" iyz="8e-06" ixz="9e-06"/>
  </inertial>
  <visual>
    <origin xyz="0.095008 0.214003 -0.17631" rpy="0 0 0"/>
    <geometry>
      <mesh filename="package://rcup_urdf_description/meshes/small_roller_v1_1.stl" scale="0.001 0.001 0.001"/>
    </geometry>
    <material name="steel_satin"/>
  </visual>
  <collision>
    <origin xyz="0.095008 0.214003 -0.17631" rpy="0 0 0"/>
    <geometry>
      <mesh filename="package://rcup_urdf_description/meshes/small_roller_v1_1.stl" scale="0.001 0.001 0.001"/>
    </geometry>
  </collision>
</link>

<link name="ROD2_1.PRT_1_1">
  <inertial>
    <origin xyz="-0.025188832166870394 -0.013717609182182872 -0.08108173194304436" rpy="0 0 0"/>
    <mass value="0.8809905481847389"/>
    <inertia ixx="0.009181" iyy="0.008966" izz="0.000535" ixy="5e-06" iyz="0.000274" ixz="1.1e-05"/>
  </inertial>
  <visual>
    <origin xyz="-0.025 0.100117 -0.245868" rpy="0 0 0"/>
    <geometry>
      <mesh filename="package://rcup_urdf_description/meshes/ROD2_1.PRT_1_1.stl" scale="0.001 0.001 0.001"/>
    </geometry>
    <material name="opaque272727"/>
  </visual>
  <collision>
    <origin xyz="-0.025 0.100117 -0.245868" rpy="0 0 0"/>
    <geometry>
      <mesh filename="package://rcup_urdf_description/meshes/ROD2_1.PRT_1_1.stl" scale="0.001 0.001 0.001"/>
    </geometry>
  </collision>
</link>

<link name="wheel_v1__1__1">
  <inertial>
    <origin xyz="-0.01000000000055598 -9.92925203154027e-06 -9.515285584092703e-06" rpy="0 0 0"/>
    <mass value="1.3762351375635922"/>
    <inertia ixx="0.001935" iyy="0.001008" izz="0.001019" ixy="0.0" iyz="1e-06" ixz="-0.0"/>
  </inertial>
  <visual>
    <origin xyz="-0.17 0.078381 -0.015" rpy="0 0 0"/>
    <geometry>
      <mesh filename="package://rcup_urdf_description/meshes/wheel_v1__1__1.stl" scale="0.001 0.001 0.001"/>
    </geometry>
    <material name="steel_satin"/>
  </visual>
  <collision>
    <origin xyz="-0.17 0.078381 -0.015" rpy="0 0 0"/>
    <geometry>
      <mesh filename="package://rcup_urdf_description/meshes/wheel_v1__1__1.stl" scale="0.001 0.001 0.001"/>
    </geometry>
  </collision>
</link>

<link name="wheel_v1__2__1">
  <inertial>
    <origin xyz="-0.009999999999999842 -9.16713600328245e-06 3.0933208643169063e-06" rpy="0 0 0"/>
    <mass value="1.3762351375635922"/>
    <inertia ixx="0.001936" iyy="0.001009" izz="0.001019" ixy="-0.0" iyz="-0.0" ixz="0.0"/>
  </inertial>
  <visual>
    <origin xyz="0.17 0.078381 -0.0125" rpy="0 0 0"/>
    <geometry>
      <mesh filename="package://rcup_urdf_description/meshes/wheel_v1__2__1.stl" scale="0.001 0.001 0.001"/>
    </geometry>
    <material name="steel_satin"/>
  </visual>
  <collision>
    <origin xyz="0.17 0.078381 -0.0125" rpy="0 0 0"/>
    <geometry>
      <mesh filename="package://rcup_urdf_description/meshes/wheel_v1__2__1.stl" scale="0.001 0.001 0.001"/>
    </geometry>
  </collision>
</link>

<joint name="Revolute 1" type="continuous">
  <origin xyz="0.17 0.167619 0.015" rpy="0 0 0"/>
  <parent link="base_link"/>
  <child link="Component417_1"/>
  <axis xyz="-1.0 0.0 0.0"/>
</joint>

<joint name="Revolute 2" type="continuous">
  <origin xyz="-0.17 0.167619 0.015" rpy="0 0 0"/>
  <parent link="base_link"/>
  <child link="wheel_v1_1"/>
  <axis xyz="-1.0 0.0 0.0"/>
</joint>

<joint name="Revolute 5" type="continuous">
  <origin xyz="0.095008 -0.214003 0.17631" rpy="0 0 0"/>
  <parent link="base_link"/>
  <child link="Component419_1"/>
  <axis xyz="0.713077 -0.534564 -0.453611"/>
</joint>

<joint name="Revolute 6" type="continuous">
  <origin xyz="-0.095008 -0.214003 0.17631" rpy="0 0 0"/>
  <parent link="base_link"/>
  <child link="small_roller_v1_1"/>
  <axis xyz="-0.713077 -0.534564 -0.453611"/>
</joint>

<joint name="Revolute 7" type="continuous">
  <origin xyz="0.025 -0.100117 0.245868" rpy="0 0 0"/>
  <parent link="base_link"/>
  <child link="ROD2_1.PRT_1_1"/>
  <axis xyz="1.0 -0.0 0.0"/>
</joint>

<joint name="Revolute 8" type="continuous">
  <origin xyz="0.17 -0.078381 0.015" rpy="0 0 0"/>
  <parent link="base_link"/>
  <child link="wheel_v1__1__1"/>
  <axis xyz="-1.0 0.0 0.0"/>
</joint>

<joint name="Revolute 9" type="continuous">
  <origin xyz="-0.17 -0.078381 0.0125" rpy="0 0 0"/>
  <parent link="base_link"/>
  <child link="wheel_v1__2__1"/>
  <axis xyz="-1.0 0.0 -0.0"/>
</joint>

</robot>
